<robot name="test_arm">
    <link name="base" >
        <visual>
            <origin xyz="0 0 0.025" rpy="0 0 0"/>
            <geometry>
                <cylinder radius=".05" length=".05"/>
            </geometry>
            <material name="Cyan1">
                <color rgba="0 0.9 0.9 1.0"/>
            </material>
        </visual>
    </link>
    <link name="link1" >
        <visual>
            <origin xyz="0 0 0.00725" rpy="0 0 0"/>
            <geometry>
                <cylinder radius=".04" length=".015"/>
            </geometry>
            <material name="Cyan1">
                <color rgba="0 0.9 0.9 1.0"/>
            </material>
        </visual>
    </link>
    <link name="link2">
        <visual>
            <origin xyz="0.0 0.0725 0.0" rpy="0 0 0"/>
            <geometry>
                <box size="0.055 0.145 0.025"/>
            </geometry>
            <material name="Black1">
                <color rgba=".2 0.2 0.2 1.0"/>
            </material>
        </visual>
    </link>
    <link name="link3">
        <visual>
            <origin xyz="0.0 0.0725 0.0" rpy="0 0 0"/>
            <geometry>
                <box size="0.025 0.145 0.025"/>
            </geometry>
            <material name="Black1">
                <color rgba=".2 0.2 0.2 1.0"/>
            </material>
        </visual>
    </link>
    <link name="link4">
        <visual>
            <origin xyz="0 0.05 0.0" rpy="0 0 0"/>
            <geometry>
                <box size="0.055 0.1 0.024"/>
            </geometry>
            <material name="Black1">
                <color rgba=".2 0.2 0.2 1.0"/>
            </material>
        </visual>
    </link>
    <link name="gripper">
        <visual>
            <origin xyz="0 0.025 0.0" rpy="0 0 0"/>
            <geometry>
                <box size="0.07 0.05 0.024"/>
            </geometry>
            <material name="Black1">
                <color rgba=".2 0.2 0.2 1.0"/>
            </material>
        </visual>
    </link>
    <link name="end_effector"/>

    <joint name="joint1" type="revolute">
        <parent link="base"/>
        <child link="link1"/>
        <origin xyz="0 0 0.05" rpy="0 0 0" />
        <axis xyz="0 0 1"/>
        <limit lower="-1.57" upper="1.57" effort="30" velocity="1.0"/>
    </joint>
    <joint name="joint2" type="revolute">
        <parent link="link1"/>
        <child link="link2"/>
        <origin xyz="0.0 0.0 0.025" rpy="0 0 0" />
        <axis xyz="1.0 0.0 0.0" />
        <limit lower="0.0" upper="1.57" effort="30" velocity="1.0"/>
    </joint>
    <joint name="joint3" type="revolute">
        <parent link="link2"/>
        <child link="link3"/>
        <origin xyz="0.00 0.145 0.0" rpy="0 0 0" />
        <axis xyz="1.0 0.0 0.0" />
        <limit lower="-1.57" upper="1.57" effort="30" velocity="1.0"/>
    </joint>
    <joint name="joint4" type="revolute">
        <parent link="link3"/>
        <child link="link4"/>
        <origin xyz="0.00 0.145 0.0" rpy="0 0 0" />
        <axis xyz="1.0 0.0 0.0" />
        <limit lower="-1.57" upper="1.57" effort="30" velocity="1.0"/>
    </joint>
    <joint name="joint5" type="revolute">
        <parent link="link4"/>
        <child link="gripper"/>
        <origin xyz="0.0 0.1 0.0" rpy="0 0 0" />
        <axis xyz="0 1.0 0.0" />
        <limit lower="-1.57" upper="1.57" effort="30" velocity="1.0"/>
    </joint>
    <joint name="joint6" type="fixed">
        <origin xyz="0.0 0.05 0.0" rpy="0 0 0" />
        <parent link="gripper"/>
        <child link="end_effector"/>
    </joint>

</robot>
